<?xml version="1.0" ?>
<!-- =================================================================================== -->
<!-- |    This document was autogenerated by xacro from rover_model.xacro              | -->
<!-- |    EDITING THIS FILE BY HAND IS NOT RECOMMENDED                                 | -->
<!-- =================================================================================== -->
<robot author="Aleksandra Grzybek" name="four_wheeled_robot">
  <!-- Converted from rover_model.sdf -->
  <!-- CHASSIS -->
  <!-- Materials -->
  <material name="wheel_mat">
    <color rgba="0.1490196 0.1490196 0.1490196 1.0"/>
  </material>
  <material name="subchassis_mat">
    <color rgba="0.3176471 0.3176471 0.3176471 1.0"/>
  </material>
  <material name="chassis_mat">
    <color rgba="0.6431373 0.6431373 0.6431373 1.0"/>
  </material>
  <link name="chassis">
    <inertial>
      <origin rpy="0 0 0" xyz="0 0 0.41000000000000003"/>
      <mass value="20.0"/>
      <inertia ixx="0.41791666666666677" ixy="0" ixz="0" iyy="1.6560416666666666" iyz="0" izz="1.4670833333333333"/>
    </inertial>
    <visual name="body_visual">
      <material name="chassis_mat"/>
      <origin rpy="0 0 0" xyz="0 0 0.41000000000000003"/>
      <geometry>
        <box size="1.055 0.65 0.24"/>
      </geometry>
    </visual>
    <collision name="body_collision">
      <origin rpy="0 0 0" xyz="0 0 0.41000000000000003"/>
      <geometry>
        <box size="1.055 0.65 0.24"/>
      </geometry>
    </collision>
  </link>
  <!-- LEFT SUBCHASSIS -->
  <link name="left_subchassis">
    <inertial>
      <origin rpy="0 0 0" xyz="0 0.41600000000000004 0.5"/>
      <mass value="6.0"/>
      <inertia ixx="0.0036" ixy="0" ixz="0" iyy="0.3546" iyz="0" izz="0.3546"/>
    </inertial>
    <visual name="left_rail_visual">
      <material name="subchassis_mat"/>
      <origin rpy="0 0 0" xyz="0 0.41600000000000004 0.5"/>
      <geometry>
        <box size="1.0 0.162 0.06"/>
      </geometry>
    </visual>
    <collision name="left_rail_collision">
      <origin rpy="0 0 0" xyz="0 0.41600000000000004 0.5"/>
      <geometry>
        <box size="1.0 0.162 0.06"/>
      </geometry>
    </collision>
  </link>
  <!-- RIGHT SUBCHASSIS -->
  <link name="right_subchassis">
    <inertial>
      <origin rpy="0 0 0" xyz="0 -0.41600000000000004 0.5"/>
      <mass value="6.0"/>
      <inertia ixx="0.0036" ixy="0" ixz="0" iyy="0.3546" iyz="0" izz="0.3546"/>
    </inertial>
    <visual name="right_rail_visual">
      <material name="subchassis_mat"/>
      <origin rpy="0 0 0" xyz="0 -0.41600000000000004 0.5"/>
      <geometry>
        <box size="1.0 0.162 0.06"/>
      </geometry>
    </visual>
    <collision name="right_rail_collision">
      <origin rpy="0 0 0" xyz="0 -0.41600000000000004 0.5"/>
      <geometry>
        <box size="1.0 0.162 0.06"/>
      </geometry>
    </collision>
  </link>
  <!-- VIRTUAL SUSPENSION DIFF -->
  <link name="suspension_diff">
    <inertial>
      <mass value="0.001"/>
      <inertia ixx="8.33333333333e-07" ixy="0" ixz="0" iyy="8.33333333333e-07" iyz="0" izz="8.33333333333e-07"/>
    </inertial>
  </link>
  <!-- WHEELS -->
  <link name="left_front_wheel">
    <inertial>
      <mass value="7.0"/>
      <inertia ixx="0.062" ixy="0" ixz="0" iyy="0.093" iyz="0" izz="0.062"/>
    </inertial>
    <visual>
      <material name="wheel_mat"/>
      <origin rpy="1.5708 0 0" xyz="0 0 0"/>
      <geometry>
        <cylinder length="0.198" radius="0.21"/>
      </geometry>
    </visual>
    <collision>
      <origin rpy="1.5708 0 0" xyz="0 0 0"/>
      <geometry>
        <cylinder length="0.198" radius="0.21"/>
      </geometry>
    </collision>
  </link>
  <link name="left_rear_wheel">
    <inertial>
      <mass value="7.0"/>
      <inertia ixx="0.062" ixy="0" ixz="0" iyy="0.093" iyz="0" izz="0.062"/>
    </inertial>
    <visual>
      <material name="wheel_mat"/>
      <origin rpy="1.5708 0 0" xyz="0 0 0"/>
      <geometry>
        <cylinder length="0.198" radius="0.21"/>
      </geometry>
    </visual>
    <collision>
      <origin rpy="1.5708 0 0" xyz="0 0 0"/>
      <geometry>
        <cylinder length="0.198" radius="0.21"/>
      </geometry>
    </collision>
  </link>
  <link name="right_front_wheel">
    <inertial>
      <mass value="7.0"/>
      <inertia ixx="0.062" ixy="0" ixz="0" iyy="0.093" iyz="0" izz="0.062"/>
    </inertial>
    <visual>
      <material name="wheel_mat"/>
      <origin rpy="1.5708 0 0" xyz="0 0 0"/>
      <geometry>
        <cylinder length="0.198" radius="0.21"/>
      </geometry>
    </visual>
    <collision>
      <origin rpy="1.5708 0 0" xyz="0 0 0"/>
      <geometry>
        <cylinder length="0.198" radius="0.21"/>
      </geometry>
    </collision>
  </link>
  <link name="right_rear_wheel">
    <inertial>
      <mass value="7.0"/>
      <inertia ixx="0.062" ixy="0" ixz="0" iyy="0.093" iyz="0" izz="0.062"/>
    </inertial>
    <visual>
      <material name="wheel_mat"/>
      <origin rpy="1.5708 0 0" xyz="0 0 0"/>
      <geometry>
        <cylinder length="0.198" radius="0.21"/>
      </geometry>
    </visual>
    <collision>
      <origin rpy="1.5708 0 0" xyz="0 0 0"/>
      <geometry>
        <cylinder length="0.198" radius="0.21"/>
      </geometry>
    </collision>
  </link>
  <!-- JOINTS -->
  <joint name="suspension_diff_joint" type="continuous">
    <parent link="chassis"/>
    <child link="suspension_diff"/>
    <axis xyz="0 1 0"/>
  </joint>
  <joint name="left_subchassis_hinge" type="continuous">
    <parent link="suspension_diff"/>
    <child link="left_subchassis"/>
    <axis xyz="0 1 0"/>
  </joint>
  <joint name="right_subchassis_hinge" type="continuous">
    <parent link="suspension_diff"/>
    <child link="right_subchassis"/>
    <axis xyz="0 1 0"/>
  </joint>
  <joint name="left_front_wheel_joint" type="continuous">
    <parent link="left_subchassis"/>
    <child link="left_front_wheel"/>
    <origin rpy="0 0 0" xyz="0.45 0.43 0.213"/>
    <axis xyz="0 1 0"/>
  </joint>
  <joint name="left_rear_wheel_joint" type="continuous">
    <parent link="left_subchassis"/>
    <child link="left_rear_wheel"/>
    <origin rpy="0 0 0" xyz="-0.45 0.43 0.213"/>
    <axis xyz="0 1 0"/>
  </joint>
  <joint name="right_front_wheel_joint" type="continuous">
    <parent link="right_subchassis"/>
    <child link="right_front_wheel"/>
    <origin rpy="0 0 0" xyz="0.45 -0.43 0.213"/>
    <axis xyz="0 1 0"/>
  </joint>
  <joint name="right_rear_wheel_joint" type="continuous">
    <parent link="right_subchassis"/>
    <child link="right_rear_wheel"/>
    <origin rpy="0 0 0" xyz="-0.45 -0.43 0.213"/>
    <axis xyz="0 1 0"/>
  </joint>
</robot>
